Workbook
Name Всебайки1: #REF!
Name проданныебайки: 'список мото'!$F$3:$F$100
Name Всемото: 'список мото'!$A:$A

Sheet клиенты
B1: AUTO CNCL | C1: Название мото | D1: Имя | E1: Дата начала | F1: Дата завершения | G1: Срок | H1: Платеж в день | I1: Долг | J1: К оплате на данный момент | K1: Оплачено | L1: Платеж в месяц (для скрипта) | M1: Платеж в день (для скрипта) | N1: Пробег на момент сдачи | O1: Последняя замена масла | P1: После последней замены масла | Q1: Текущий пробег с датой | R1: Дата отметки текущего пробега | S1: Залог | T1: Шлем | U1: Контакты | V1: Примечание | W1: Для скрипта и проверки | X1: Тип для скрипта
A2: Завершена | B2: OFF | C2: PCX 150CC GREY PHUKET 778 | D2: Рената | E2: 44812 | F2: 44819 | G2: =IF((E2="")+(F2=""), "", IF(DATEDIF(E2, F2, "d") > 30, DATEDIF(E2, F2, "m") & " М", DATEDIF(E2, F2, "d") & " Д")) -> 7 Д | H2: =1500/7 -> 214.28571 | I2: =IF(OR(A2="в аренде", A2="в аренде 1", A2="в аренде 2"), J2-K2, "") | J2: =IF(OR(A2="в аренде", A2="в аренде 1", A2="в аренде 2"), DATEDIF(E2, TODAY(), "D")*H2, "") | K2: 1500 | N2: 15970 | O2: =IFERROR(__xludf.DUMMYFUNCTION("IFERROR( VLOOKUP(C2, FILTER( IMPORTRANGE(""https://docs.google.com/spreadsheets/d/1ZBCmVvzoFu7X0td7O5T5xSJplK8m8h9wvdESBc0a1EE/edit#gid=1841437934"", ""Лист1!$C:$I""), IMPORTRANGE(""https://docs.google.com/spreadsheets/d/1ZBCmVvzoFu7X0t"&"d7O5T5xSJplK8m8h9wvdESBc0a1EE/edit#gid=1841437934"", ""Лист1!$C:$C"") = C2 ), 7, FALSE ), """" ) "),"") | P2: =IFERROR(__xludf.DUMMYFUNCTION("IF(OR(ISBLANK(Q2), ISBLANK(O2), VALUE(SUBSTITUTE(INDEX(SPLIT(IF(ISBLANK(R2), Q2, R2), "" km""), 0, 1), "" "", """")) - O2 = 0), """", IF(ISBLANK(R2), VALUE(SUBSTITUTE(INDEX(SPLIT(Q2, "" km""), 0, 1), "" "", """")) - O2, VALUE(SUBSTITUTE(INDEX(SPLIT(R2, """&" km""), 0, 1), "" "", """")) - O2))"),"#VALUE!") -> #VALUE! | Q2: =IF(AND(ISBLANK(N2), ISBLANK(E2), ISBLANK(R2)), "", IF(ISBLANK(R2), TEXT(N2, "#,##0") & " Km, " & TEXT(E2, "dd.mm.yyyy"), R2)) -> коцки низа | R2: коцки низа | S2: 500 вычел | T2: 1 | U2: @Arreeonelove +918767219725 | V2: пьяненькая неуверненная | W2: =IF(F2 = "", "", IF(NOW() > (DATEVALUE(LEFT(F2, SEARCH(",", F2) - 2)) + TIMEVALUE(MID(F2, SEARCH(",", F2) + 2, 5))), "Завершена", "В аренде")) -> Завершена | X2: =IFERROR(__xludf.DUMMYFUNCTION("IF(C2 = """", """", IF(REGEXMATCH(C2, ""PCX|NMAX|ADV|CLICK""), ""скутер"", ""мото""))"),"скутер") -> скутер
A3: Завершена | B3: OFF | C3: XMAX 300CC GREY PHUKET 4246 | D3: Сергей | E3: 44817 | F3: 44908 | G3: =IF((E3="")+(F3=""), "", IF(DATEDIF(E3, F3, "d") > 30, DATEDIF(E3, F3, "m") & " М", DATEDIF(E3, F3, "d") & " Д")) -> 3 М | H3: 333.33 | I3: =IF(OR(A3="в аренде", A3="в аренде 1", A3="в аренде 2"), J3-K3, "") | J3: =IF(OR(A3="в аренде", A3="в аренде 1", A3="в аренде 2"), DATEDIF(E3, TODAY(), "D")*H3, "") | K3: 20000 | N3: 11080 | O3: =IFERROR(__xludf.DUMMYFUNCTION("IFERROR( VLOOKUP(C3, FILTER( IMPORTRANGE(""https://docs.google.com/spreadsheets/d/1ZBCmVvzoFu7X0td7O5T5xSJplK8m8h9wvdESBc0a1EE/edit#gid=1841437934"", ""Лист1!$C:$I""), IMPORTRANGE(""https://docs.google.com/spreadsheets/d/1ZBCmVvzoFu7X0t"&"d7O5T5xSJplK8m8h9wvdESBc0a1EE/edit#gid=1841437934"", ""Лист1!$C:$C"") = C3 ), 7, FALSE ), """" ) "),38640.0) -> 38640 | P3: =IFERROR(__xludf.DUMMYFUNCTION("IF(OR(ISBLANK(Q3), ISBLANK(O3), VALUE(SUBSTITUTE(INDEX(SPLIT(IF(ISBLANK(R3), Q3, R3), "" km""), 0, 1), "" "", """")) - O3 = 0), """", IF(ISBLANK(R3), VALUE(SUBSTITUTE(INDEX(SPLIT(Q3, "" km""), 0, 1), "" "", """")) - O3, VALUE(SUBSTITUTE(INDEX(SPLIT(R3, """&" km""), 0, 1), "" "", """")) - O3))"),-27560.0) -> -27560 | Q3: =IF(AND(ISBLANK(N3), ISBLANK(E3), ISBLANK(R3)), "", IF(ISBLANK(R3), TEXT(N3, "#,##0") & " Km, " & TEXT(E3, "dd.mm.yyyy"), R3)) -> 11 080 Km, 13.09.2022 | S3: 5000 | T3: - | U3: @penytwice +66617412035 | V3: вроде опытный живет в тае | W3: =IF(F3 = "", "", IF(NOW() > (DATEVALUE(LEFT(F3, SEARCH(",", F3) - 2)) + TIMEVALUE(MID(F3, SEARCH(",", F3) + 2, 5))), "Завершена", "В аренде")) -> Завершена | X3: =IFERROR(__xludf.DUMMYFUNCTION("IF(C3 = """", """", IF(REGEXMATCH(C3, ""PCX|NMAX|ADV|CLICK""), ""скутер"", ""мото""))"),"мото") -> мото
A4: Завершена | B4: OFF | C4: FORZA 300CC GREY PHUKET 4234 | D4: Андрей | E4: 44835 | F4: 44866 | G4: =IF((E4="")+(F4=""), "", IF(DATEDIF(E4, F4, "d") > 30, DATEDIF(E4, F4, "m") & " М", DATEDIF(E4, F4, "d") & " Д")) -> 1 М | H4: =11000/30 -> 366.66667 | I4: =IF(OR(A4="в аренде", A4="в аренде 1", A4="в аренде 2"), J4-K4, "") | J4: =IF(OR(A4="в аренде", A4="в аренде 1", A4="в аренде 2"), DATEDIF(E4, TODAY(), "D")*H4, "") | K4: 11000 | N4: 17273 | O4: =IFERROR(__xludf.DUMMYFUNCTION("IFERROR( VLOOKUP(C4, FILTER( IMPORTRANGE(""https://docs.google.com/spreadsheets/d/1ZBCmVvzoFu7X0td7O5T5xSJplK8m8h9wvdESBc0a1EE/edit#gid=1841437934"", ""Лист1!$C:$I""), IMPORTRANGE(""https://docs.google.com/spreadsheets/d/1ZBCmVvzoFu7X0t"&"d7O5T5xSJplK8m8h9wvdESBc0a1EE/edit#gid=1841437934"", ""Лист1!$C:$C"") = C4 ), 7, FALSE ), """" ) "),"") | P4: =IFERROR(__xludf.DUMMYFUNCTION("IF(OR(ISBLANK(Q4), ISBLANK(O4), VALUE(SUBSTITUTE(INDEX(SPLIT(IF(ISBLANK(R4), Q4, R4), "" km""), 0, 1), "" "", """")) - O4 = 0), """", IF(ISBLANK(R4), VALUE(SUBSTITUTE(INDEX(SPLIT(Q4, "" km""), 0, 1), "" "", """")) - O4, VALUE(SUBSTITUTE(INDEX(SPLIT(R4, """&" km""), 0, 1), "" "", """")) - O4))"),17273.0) -> 17273 | Q4: =IF(AND(ISBLANK(N4), ISBLANK(E4), ISBLANK(R4)), "", IF(ISBLANK(R4), TEXT(N4, "#,##0") & " Km, " & TEXT(E4, "dd.mm.yyyy"), R4)) -> 17 273 Km, 01.10.2022 | S4: 5000 | T4: 2 | U4: @marbok 943375719 | V4: гуд мотоджимхана | W4: =IF(F4 = "", "", IF(NOW() > (DATEVALUE(LEFT(F4, SEARCH(",", F4) - 2)) + TIMEVALUE(MID(F4, SEARCH(",", F4) + 2, 5))), "Завершена", "В аренде")) -> Завершена | X4: =IFERROR(__xludf.DUMMYFUNCTION("IF(C4 = """", """", IF(REGEXMATCH(C4, ""PCX|NMAX|ADV|CLICK""), ""скутер"", ""мото""))"),"мото") -> мото
A5: Завершена | B5: OFF | C5: PCX 150CC GREY PHUKET 778 | D5: Никита Моисеев | E5: 44837 | F5: 44844 | G5: =IF((E5="")+(F5=""), "", IF(DATEDIF(E5, F5, "d") > 30, DATEDIF(E5, F5, "m") & " М", DATEDIF(E5, F5, "d") & " Д")) -> 7 Д | H5: 250 | I5: =IF(OR(A5="в аренде", A5="в аренде 1", A5="в аренде 2"), J5-K5, "") | J5: =IF(OR(A5="в аренде", A5="в аренде 1", A5="в аренде 2"), DATEDIF(E5, TODAY(), "D")*H5, "") | K5: 1500 | N5: 16200 | O5: =IFERROR(__xludf.DUMMYFUNCTION("IFERROR( VLOOKUP(C5, FILTER( IMPORTRANGE(""https://docs.google.com/spreadsheets/d/1ZBCmVvzoFu7X0td7O5T5xSJplK8m8h9wvdESBc0a1EE/edit#gid=1841437934"", ""Лист1!$C:$I""), IMPORTRANGE(""https://docs.google.com/spreadsheets/d/1ZBCmVvzoFu7X0t"&"d7O5T5xSJplK8m8h9wvdESBc0a1EE/edit#gid=1841437934"", ""Лист1!$C:$C"") = C5 ), 7, FALSE ), """" ) "),"") | P5: =IFERROR(__xludf.DUMMYFUNCTION("IF(OR(ISBLANK(Q5), ISBLANK(O5), VALUE(SUBSTITUTE(INDEX(SPLIT(IF(ISBLANK(R5), Q5, R5), "" km""), 0, 1), "" "", """")) - O5 = 0), """", IF(ISBLANK(R5), VALUE(SUBSTITUTE(INDEX(SPLIT(Q5, "" km""), 0, 1), "" "", """")) - O5, VALUE(SUBSTITUTE(INDEX(SPLIT(R5, """&" km""), 0, 1), "" "", """")) - O5))"),16200.0) -> 16200 | Q5: =IF(AND(ISBLANK(N5), ISBLANK(E5), ISBLANK(R5)), "", IF(ISBLANK(R5), TEXT(N5, "#,##0") & " Km, " & TEXT(E5, "dd.mm.yyyy"), R5)) -> 16 200 Km, 03.10.2022 | S5: 3000 | T5: 2 | U5: @spacegilly +79958803610 | V5: Мутный Арбитражник возможно скамер | W5: =IF(F5 = "", "", IF(NOW() > (DATEVALUE(LEFT(F5, SEARCH(",", F5) - 2)) + TIMEVALUE(MID(F5, SEARCH(",", F5) + 2, 5))), "Завершена", "В аренде")) -> Завершена | X5: =IFERROR(__xludf.DUMMYFUNCTION("IF(C5 = """", """", IF(REGEXMATCH(C5, ""PCX|NMAX|ADV|CLICK""), ""скутер"", ""мото""))"),"скутер") -> скутер
A6: Завершена | B6: OFF | C6: NMAX 155CC GREEN-B PHUKET 4957 | D6: Andrei друг | E6: 44852 | F6: 44975 | G6: =IF((E6="")+(F6=""), "", IF(DATEDIF(E6, F6, "d") > 30, DATEDIF(E6, F6, "m") & " М", DATEDIF(E6, F6, "d") & " Д")) -> 4 М | H6: =5800/30 -> 193.33333 | I6: =IF(OR(A6="в аренде", A6="в аренде 1", A6="в аренде 2"), J6-K6, "") | J6: =IF(OR(A6="в аренде", A6="в аренде 1", A6="в аренде 2"), DATEDIF(E6, TODAY(), "D")*H6, "") | K6: =5800+5800+5800+1500 -> 18900 | N6: 12800 | O6: =IFERROR(__xludf.DUMMYFUNCTION("IFERROR( VLOOKUP(C6, FILTER( IMPORTRANGE(""https://docs.google.com/spreadsheets/d/1ZBCmVvzoFu7X0td7O5T5xSJplK8m8h9wvdESBc0a1EE/edit#gid=1841437934"", ""Лист1!$C:$I""), IMPORTRANGE(""https://docs.google.com/spreadsheets/d/1ZBCmVvzoFu7X0t"&"d7O5T5xSJplK8m8h9wvdESBc0a1EE/edit#gid=1841437934"", ""Лист1!$C:$C"") = C6 ), 7, FALSE ), """" ) "),30800.0) -> 30800 | P6: =IFERROR(__xludf.DUMMYFUNCTION("IF(OR(ISBLANK(Q6), ISBLANK(O6), VALUE(SUBSTITUTE(INDEX(SPLIT(IF(ISBLANK(R6), Q6, R6), "" km""), 0, 1), "" "", """")) - O6 = 0), """", IF(ISBLANK(R6), VALUE(SUBSTITUTE(INDEX(SPLIT(Q6, "" km""), 0, 1), "" "", """")) - O6, VALUE(SUBSTITUTE(INDEX(SPLIT(R6, """&" km""), 0, 1), "" "", """")) - O6))"),-18000.0) -> -18000 | Q6: =IF(AND(ISBLANK(N6), ISBLANK(E6), ISBLANK(R6)), "", IF(ISBLANK(R6), TEXT(N6, "#,##0") & " Km, " & TEXT(E6, "dd.mm.yyyy"), R6)) -> 12 800 Km, 18.10.2022 | S6: 3000 | T6: 1 | U6: @Maskellanear +6695291890 | V6: молодой но вроде опыт есть | W6: =IF(F6 = "", "", IF(NOW() > (DATEVALUE(LEFT(F6, SEARCH(",", F6) - 2)) + TIMEVALUE(MID(F6, SEARCH(",", F6) + 2, 5))), "Завершена", "В аренде")) -> Завершена | X6: =IFERROR(__xludf.DUMMYFUNCTION("IF(C6 = """", """", IF(REGEXMATCH(C6, ""PCX|NMAX|ADV|CLICK""), ""скутер"", ""мото""))"),"скутер") -> скутер
A7: Завершена | B7: OFF | C7: NMAX 155CC BLACK GREEN PHUKET 4253 | D7: Дарья | E7: 44854 | F7: 45005 | G7: =IF((E7="")+(F7=""), "", IF(DATEDIF(E7, F7, "d") > 30, DATEDIF(E7, F7, "m") & " М", DATEDIF(E7, F7, "d") & " Д")) -> 5 М | H7: =6000/30 -> 200 | I7: =IF(OR(A7="в аренде", A7="в аренде 1", A7="в аренде 2"), J7-K7, "") | J7: =IF(OR(A7="в аренде", A7="в аренде 1", A7="в аренде 2"), DATEDIF(E7, TODAY(), "D")*H7, "") | K7: =6000+6000+6000+6000 -> 24000 | N7: 17300 | O7: =IFERROR(__xludf.DUMMYFUNCTION("IFERROR( VLOOKUP(C7, FILTER( IMPORTRANGE(""https://docs.google.com/spreadsheets/d/1ZBCmVvzoFu7X0td7O5T5xSJplK8m8h9wvdESBc0a1EE/edit#gid=1841437934"", ""Лист1!$C:$I""), IMPORTRANGE(""https://docs.google.com/spreadsheets/d/1ZBCmVvzoFu7X0t"&"d7O5T5xSJplK8m8h9wvdESBc0a1EE/edit#gid=1841437934"", ""Лист1!$C:$C"") = C7 ), 7, FALSE ), """" ) "),35800.0) -> 35800 | P7: =IFERROR(__xludf.DUMMYFUNCTION("IF(OR(ISBLANK(Q7), ISBLANK(O7), VALUE(SUBSTITUTE(INDEX(SPLIT(IF(ISBLANK(R7), Q7, R7), "" km""), 0, 1), "" "", """")) - O7 = 0), """", IF(ISBLANK(R7), VALUE(SUBSTITUTE(INDEX(SPLIT(Q7, "" km""), 0, 1), "" "", """")) - O7, VALUE(SUBSTITUTE(INDEX(SPLIT(R7, """&" km""), 0, 1), "" "", """")) - O7))"),-18500.0) -> -18500 | Q7: =IF(AND(ISBLANK(N7), ISBLANK(E7), ISBLANK(R7)), "", IF(ISBLANK(R7), TEXT(N7, "#,##0") & " Km, " & TEXT(E7, "dd.mm.yyyy"), R7)) -> 17 300 Km, 20.10.2022 | S7: 3000 | T7: - | U7: @daria2dare | V7: на вид ок | W7: =IF(F7 = "", "", IF(NOW() > (DATEVALUE(LEFT(F7, SEARCH(",", F7) - 2)) + TIMEVALUE(MID(F7, SEARCH(",", F7) + 2, 5))), "Завершена", "В аренде")) -> Завершена | X7: =IFERROR(__xludf.DUMMYFUNCTION("IF(C7 = """", """", IF(REGEXMATCH(C7, ""PCX|NMAX|ADV|CLICK""), ""скутер"", ""мото""))"),"скутер") -> скутер
A8: Завершена | B8: OFF | C8: CLICK 125CC PHUKET 5580 | D8: Дима | E8: 44855 | F8: 44886 | G8: =IF((E8="")+(F8=""), "", IF(DATEDIF(E8, F8, "d") > 30, DATEDIF(E8, F8, "m") & " М", DATEDIF(E8, F8, "d") & " Д")) -> 1 М | H8: =4000/30 -> 133.33333 | I8: =IF(OR(A8="в аренде", A8="в аренде 1", A8="в аренде 2"), J8-K8, "") | J8: =IF(OR(A8="в аренде", A8="в аренде 1", A8="в аренде 2"), DATEDIF(E8, TODAY(), "D")*H8, "") | K8: 4000 | N8: 26720 | O8: =IFERROR(__xludf.DUMMYFUNCTION("IFERROR( VLOOKUP(C8, FILTER( IMPORTRANGE(""https://docs.google.com/spreadsheets/d/1ZBCmVvzoFu7X0td7O5T5xSJplK8m8h9wvdESBc0a1EE/edit#gid=1841437934"", ""Лист1!$C:$I""), IMPORTRANGE(""https://docs.google.com/spreadsheets/d/1ZBCmVvzoFu7X0t"&"d7O5T5xSJplK8m8h9wvdESBc0a1EE/edit#gid=1841437934"", ""Лист1!$C:$C"") = C8 ), 7, FALSE ), """" ) "),33515.0) -> 33515 | P8: =IFERROR(__xludf.DUMMYFUNCTION("IF(OR(ISBLANK(Q8), ISBLANK(O8), VALUE(SUBSTITUTE(INDEX(SPLIT(IF(ISBLANK(R8), Q8, R8), "" km""), 0, 1), "" "", """")) - O8 = 0), """", IF(ISBLANK(R8), VALUE(SUBSTITUTE(INDEX(SPLIT(Q8, "" km""), 0, 1), "" "", """")) - O8, VALUE(SUBSTITUTE(INDEX(SPLIT(R8, """&" km""), 0, 1), "" "", """")) - O8))"),-6795.0) -> -6795 | Q8: =IF(AND(ISBLANK(N8), ISBLANK(E8), ISBLANK(R8)), "", IF(ISBLANK(R8), TEXT(N8, "#,##0") & " Km, " & TEXT(E8, "dd.mm.yyyy"), R8)) -> 26 720 Km, 21.10.2022 | S8: 3000 | T8: 1 | U8: @dimanetesov | V8: опыта нет вроде норм чел с другом @egorovcrz | W8: =IF(F8 = "", "", IF(NOW() > (DATEVALUE(LEFT(F8, SEARCH(",", F8) - 2)) + TIMEVALUE(MID(F8, SEARCH(",", F8) + 2, 5))), "Завершена", "В аренде")) -> Завершена | X8: =IFERROR(__xludf.DUMMYFUNCTION("IF(C8 = """", """", IF(REGEXMATCH(C8, ""PCX|NMAX|ADV|CLICK""), ""скутер"", ""мото""))"),"скутер") -> скутер
A9: Завершена | B9: OFF | C9: NMAX 155CC BLACK GOLD-2 PHUKET 4685 | D9: Тарас | E9: 44855 | F9: 44894 | G9: =IF((E9="")+(F9=""), "", IF(DATEDIF(E9, F9, "d") > 30, DATEDIF(E9, F9, "m") & " М", DATEDIF(E9, F9, "d") & " Д")) -> 1 М | H9: =6500/30 -> 216.66667 | I9: =IF(OR(A9="в аренде", A9="в аренде 1", A9="в аренде 2"), J9-K9, "") | J9: =IF(OR(A9="в аренде", A9="в аренде 1", A9="в аренде 2"), DATEDIF(E9, TODAY(), "D")*H9, "") | K9: =7000+1500 -> 8500 | N9: 19300 | O9: =IFERROR(__xludf.DUMMYFUNCTION("IFERROR( VLOOKUP(C9, FILTER( IMPORTRANGE(""https://docs.google.com/spreadsheets/d/1ZBCmVvzoFu7X0td7O5T5xSJplK8m8h9wvdESBc0a1EE/edit#gid=1841437934"", ""Лист1!$C:$I""), IMPORTRANGE(""https://docs.google.com/spreadsheets/d/1ZBCmVvzoFu7X0t"&"d7O5T5xSJplK8m8h9wvdESBc0a1EE/edit#gid=1841437934"", ""Лист1!$C:$C"") = C9 ), 7, FALSE ), """" ) "),36400.0) -> 36400 | P9: =IFERROR(__xludf.DUMMYFUNCTION("IF(OR(ISBLANK(Q9), ISBLANK(O9), VALUE(SUBSTITUTE(INDEX(SPLIT(IF(ISBLANK(R9), Q9, R9), "" km""), 0, 1), "" "", """")) - O9 = 0), """", IF(ISBLANK(R9), VALUE(SUBSTITUTE(INDEX(SPLIT(Q9, "" km""), 0, 1), "" "", """")) - O9, VALUE(SUBSTITUTE(INDEX(SPLIT(R9, """&" km""), 0, 1), "" "", """")) - O9))"),-17100.0) -> -17100 | Q9: =IF(AND(ISBLANK(N9), ISBLANK(E9), ISBLANK(R9)), "", IF(ISBLANK(R9), TEXT(N9, "#,##0") & " Km, " & TEXT(E9, "dd.mm.yyyy"), R9)) -> 19 300 Km, 21.10.2022 | S9: 3000 | T9: 2 | U9: @Danin_12 | V9: укр гуд ребята опытные | W9: =IF(F9 = "", "", IF(NOW() > (DATEVALUE(LEFT(F9, SEARCH(",", F9) - 2)) + TIMEVALUE(MID(F9, SEARCH(",", F9) + 2, 5))), "Завершена", "В аренде")) -> Завершена | X9: =IFERROR(__xludf.DUMMYFUNCTION("IF(C9 = """", """", IF(REGEXMATCH(C9, ""PCX|NMAX|ADV|CLICK""), ""скутер"", ""мото""))"),"скутер") -> скутер
A10: Завершена | B10: OFF | C10: FORZA 300CC RED PHUKET 4244 | D10: Алексей | E10: 44855 | F10: 44947 | G10: =IF((E10="")+(F10=""), "", IF(DATEDIF(E10, F10, "d") > 30, DATEDIF(E10, F10, "m") & " М", DATEDIF(E10, F10, "d") & " Д")) -> 3 М | H10: =5500/30 -> 183.33333 | I10: =IF(OR(A10="в аренде", A10="в аренде 1", A10="в аренде 2"), J10-K10, "") | J10: =IF(OR(A10="в аренде", A10="в аренде 1", A10="в аренде 2"), DATEDIF(E10, TODAY(), "D")*H10, "") | K10: 5500 | N10: 24000 | O10: =IFERROR(__xludf.DUMMYFUNCTION("IFERROR( VLOOKUP(C10, FILTER( IMPORTRANGE(""https://docs.google.com/spreadsheets/d/1ZBCmVvzoFu7X0td7O5T5xSJplK8m8h9wvdESBc0a1EE/edit#gid=1841437934"", ""Лист1!$C:$I""), IMPORTRANGE(""https://docs.google.com/spreadsheets/d/1ZBCmVvzoFu7X0"&"td7O5T5xSJplK8m8h9wvdESBc0a1EE/edit#gid=1841437934"", ""Лист1!$C:$C"") = C10 ), 7, FALSE ), """" ) "),"") | P10: =IFERROR(__xludf.DUMMYFUNCTION("IF(OR(ISBLANK(Q10), ISBLANK(O10), VALUE(SUBSTITUTE(INDEX(SPLIT(IF(ISBLANK(R10), Q10, R10), "" km""), 0, 1), "" "", """")) - O10 = 0), """", IF(ISBLANK(R10), VALUE(SUBSTITUTE(INDEX(SPLIT(Q10, "" km""), 0, 1), "" "", """")) - O10, VALUE(SUBSTITUTE(INDEX(SPL"&"IT(R10, "" km""), 0, 1), "" "", """")) - O10))"),24000.0) -> 24000 | Q10: =IF(AND(ISBLANK(N10), ISBLANK(E10), ISBLANK(R10)), "", IF(ISBLANK(R10), TEXT(N10, "#,##0") & " Km, " & TEXT(E10, "dd.mm.yyyy"), R10)) -> 24 000 Km, 21.10.2022 | S10: 3000 | T10: 1 | U10: @egorovcrz | V10: опыт есть вроде норм чел с другом @dimanesterov | W10: =IF(F10 = "", "", IF(NOW() > (DATEVALUE(LEFT(F10, SEARCH(",", F10) - 2)) + TIMEVALUE(MID(F10, SEARCH(",", F10) + 2, 5))), "Завершена", "В аренде")) -> Завершена | X10: =IFERROR(__xludf.DUMMYFUNCTION("IF(C10 = """", """", IF(REGEXMATCH(C10, ""PCX|NMAX|ADV|CLICK""), ""скутер"", ""мото""))"),"мото") -> мото
A11: Завершена | B11: OFF | C11: XMAX 300CC GREEN PHUKET 4248 | D11: Анатолий | E11: 44856 | F11: 44948 | G11: =IF((E11="")+(F11=""), "", IF(DATEDIF(E11, F11, "d") > 30, DATEDIF(E11, F11, "m") & " М", DATEDIF(E11, F11, "d") & " Д")) -> 3 М | H11: =13000/30 -> 433.33333 | I11: =IF(OR(A11="в аренде", A11="в аренде 1", A11="в аренде 2"), J11-K11, "") | J11: =IF(OR(A11="в аренде", A11="в аренде 1", A11="в аренде 2"), DATEDIF(E11, TODAY(), "D")*H11, "") | K11: =13000+13000+13000 -> 39000 | N11: 9900 | O11: =IFERROR(__xludf.DUMMYFUNCTION("IFERROR( VLOOKUP(C11, FILTER( IMPORTRANGE(""https://docs.google.com/spreadsheets/d/1ZBCmVvzoFu7X0td7O5T5xSJplK8m8h9wvdESBc0a1EE/edit#gid=1841437934"", ""Лист1!$C:$I""), IMPORTRANGE(""https://docs.google.com/spreadsheets/d/1ZBCmVvzoFu7X0"&"td7O5T5xSJplK8m8h9wvdESBc0a1EE/edit#gid=1841437934"", ""Лист1!$C:$C"") = C11 ), 7, FALSE ), """" ) "),32600.0) -> 32600 | P11: =IFERROR(__xludf.DUMMYFUNCTION("IF(OR(ISBLANK(Q11), ISBLANK(O11), VALUE(SUBSTITUTE(INDEX(SPLIT(IF(ISBLANK(R11), Q11, R11), "" km""), 0, 1), "" "", """")) - O11 = 0), """", IF(ISBLANK(R11), VALUE(SUBSTITUTE(INDEX(SPLIT(Q11, "" km""), 0, 1), "" "", """")) - O11, VALUE(SUBSTITUTE(INDEX(SPL"&"IT(R11, "" km""), 0, 1), "" "", """")) - O11))"),-22700.0) -> -22700 | Q11: =IF(AND(ISBLANK(N11), ISBLANK(E11), ISBLANK(R11)), "", IF(ISBLANK(R11), TEXT(N11, "#,##0") & " Km, " & TEXT(E11, "dd.mm.yyyy"), R11)) -> 9 900 Km, 22.10.2022 | S11: 5000 | T11: 1 | U11: @proxwian | V11: прогер не очень опытный но норм | W11: =IF(F11 = "", "", IF(NOW() > (DATEVALUE(LEFT(F11, SEARCH(",", F11) - 2)) + TIMEVALUE(MID(F11, SEARCH(",", F11) + 2, 5))), "Завершена", "В аренде")) -> Завершена | X11: =IFERROR(__xludf.DUMMYFUNCTION("IF(C11 = """", """", IF(REGEXMATCH(C11, ""PCX|NMAX|ADV|CLICK""), ""скутер"", ""мото""))"),"мото") -> мото
A12: Завершена | B12: OFF | C12: NMAX 155CC BLACK GOLD PHUKET 4255 | D12: Павел | E12: 44856 | F12: 44948 | G12: =IF((E12="")+(F12=""), "", IF(DATEDIF(E12, F12, "d") > 30, DATEDIF(E12, F12, "m") & " М", DATEDIF(E12, F12, "d") & " Д")) -> 3 М | H12: =7000/30 -> 233.33333 | I12: =IF(OR(A12="в аренде", A12="в аренде 1", A12="в аренде 2"), J12-K12, "") | J12: =IF(OR(A12="в аренде", A12="в аренде 1", A12="в аренде 2"), DATEDIF(E12, TODAY(), "D")*H12, "") | K12: =7000+7000 -> 14000 | N12: 29275 | O12: =IFERROR(__xludf.DUMMYFUNCTION("IFERROR( VLOOKUP(C12, FILTER( IMPORTRANGE(""https://docs.google.com/spreadsheets/d/1ZBCmVvzoFu7X0td7O5T5xSJplK8m8h9wvdESBc0a1EE/edit#gid=1841437934"", ""Лист1!$C:$I""), IMPORTRANGE(""https://docs.google.com/spreadsheets/d/1ZBCmVvzoFu7X0"&"td7O5T5xSJplK8m8h9wvdESBc0a1EE/edit#gid=1841437934"", ""Лист1!$C:$C"") = C12 ), 7, FALSE ), """" ) "),24094.0) -> 24094 | P12: =IFERROR(__xludf.DUMMYFUNCTION("IF(OR(ISBLANK(Q12), ISBLANK(O12), VALUE(SUBSTITUTE(INDEX(SPLIT(IF(ISBLANK(R12), Q12, R12), "" km""), 0, 1), "" "", """")) - O12 = 0), """", IF(ISBLANK(R12), VALUE(SUBSTITUTE(INDEX(SPLIT(Q12, "" km""), 0, 1), "" "", """")) - O12, VALUE(SUBSTITUTE(INDEX(SPL"&"IT(R12, "" km""), 0, 1), "" "", """")) - O12))"),5181.0) -> 5181 | Q12: =IF(AND(ISBLANK(N12), ISBLANK(E12), ISBLANK(R12)), "", IF(ISBLANK(R12), TEXT(N12, "#,##0") & " Km, " & TEXT(E12, "dd.mm.yyyy"), R12)) -> 29 275 Km, 22.10.2022 | S12: =3000 -> 3000 | T12: 1 | U12: @TarasovPS | V12: странный неопытный | W12: =IF(F12 = "", "", IF(NOW() > (DATEVALUE(LEFT(F12, SEARCH(",", F12) - 2)) + TIMEVALUE(MID(F12, SEARCH(",", F12) + 2, 5))), "Завершена", "В аренде")) -> Завершена | X12: =IFERROR(__xludf.DUMMYFUNCTION("IF(C12 = """", """", IF(REGEXMATCH(C12, ""PCX|NMAX|ADV|CLICK""), ""скутер"", ""мото""))"),"скутер") -> скутер
A13: Завершена | B13: OFF | C13: PCX 150CC GREY PHUKET 778 | D13: Никита Моисеев | E13: 44858 | F13: 45005 | G13: =IF((E13="")+(F13=""), "", IF(DATEDIF(E13, F13, "d") > 30, DATEDIF(E13, F13, "m") & " М", DATEDIF(E13, F13, "d") & " Д")) -> 4 М | H13: 250 | I13: =IF(OR(A13="в аренде", A13="в аренде 1", A13="в аренде 2"), J13-K13, "") | J13: =IF(OR(A13="в аренде", A13="в аренде 1", A13="в аренде 2"), DATEDIF(E13, TODAY(), "D")*H13, "") | K13: =1500+1750+1750+1750+1750+1750+200+1550+1750+3500+1750+750+1000+1750+1750+1750+1750+1750+660+1090+500 -> 31750 | N13: 16800 | O13: =IFERROR(__xludf.DUMMYFUNCTION("IFERROR( VLOOKUP(C13, FILTER( IMPORTRANGE(""https://docs.google.com/spreadsheets/d/1ZBCmVvzoFu7X0td7O5T5xSJplK8m8h9wvdESBc0a1EE/edit#gid=1841437934"", ""Лист1!$C:$I""), IMPORTRANGE(""https://docs.google.com/spreadsheets/d/1ZBCmVvzoFu7X0"&"td7O5T5xSJplK8m8h9wvdESBc0a1EE/edit#gid=1841437934"", ""Лист1!$C:$C"") = C13 ), 7, FALSE ), """" ) "),"") | P13: =IFERROR(__xludf.DUMMYFUNCTION("IF(OR(ISBLANK(Q13), ISBLANK(O13), VALUE(SUBSTITUTE(INDEX(SPLIT(IF(ISBLANK(R13), Q13, R13), "" km""), 0, 1), "" "", """")) - O13 = 0), """", IF(ISBLANK(R13), VALUE(SUBSTITUTE(INDEX(SPLIT(Q13, "" km""), 0, 1), "" "", """")) - O13, VALUE(SUBSTITUTE(INDEX(SPL"&"IT(R13, "" km""), 0, 1), "" "", """")) - O13))"),16800.0) -> 16800 | Q13: =IF(AND(ISBLANK(N13), ISBLANK(E13), ISBLANK(R13)), "", IF(ISBLANK(R13), TEXT(N13, "#,##0") & " Km, " & TEXT(E13, "dd.mm.yyyy"), R13)) -> 16 800 Km, 24.10.2022 | S13: 3000 | T13: 1 | U13: @spacegilly +79958803611 | V13: Мутный Арбитражник возможно скамер | W13: =IF(F13 = "", "", IF(NOW() > (DATEVALUE(LEFT(F13, SEARCH(",", F13) - 2)) + TIMEVALUE(MID(F13, SEARCH(",", F13) + 2, 5))), "Завершена", "В аренде")) -> Завершена | X13: =IFERROR(__xludf.DUMMYFUNCTION("IF(C13 = """", """", IF(REGEXMATCH(C13, ""PCX|NMAX|ADV|CLICK""), ""скутер"", ""мото""))"),"скутер") -> скутер
A14: Завершена | B14: OFF | C14: NMAX 155CC BLACK GOLD-3 PHUKET 7530 | D14: Максим | E14: 44865 | F14: 44985 | G14: =IF((E14="")+(F14=""), "", IF(DATEDIF(E14, F14, "d") > 30, DATEDIF(E14, F14, "m") & " М", DATEDIF(E14, F14, "d") & " Д")) -> 3 М | H14: =7000/30 -> 233.33333 | I14: =IF(OR(A14="в аренде", A14="в аренде 1", A14="в аренде 2"), J14-K14, "") | J14: =IF(OR(A14="в аренде", A14="в аренде 1", A14="в аренде 2"), DATEDIF(E14, TODAY(), "D")*H14, "") | K14: 24000 | N14: 33000 | O14: =IFERROR(__xludf.DUMMYFUNCTION("IFERROR( VLOOKUP(C14, FILTER( IMPORTRANGE(""https://docs.google.com/spreadsheets/d/1ZBCmVvzoFu7X0td7O5T5xSJplK8m8h9wvdESBc0a1EE/edit#gid=1841437934"", ""Лист1!$C:$I""), IMPORTRANGE(""https://docs.google.com/spreadsheets/d/1ZBCmVvzoFu7X0"&"td7O5T5xSJplK8m8h9wvdESBc0a1EE/edit#gid=1841437934"", ""Лист1!$C:$C"") = C14 ), 7, FALSE ), """" ) "),31000.0) -> 31000 | P14: =IFERROR(__xludf.DUMMYFUNCTION("IF(OR(ISBLANK(Q14), ISBLANK(O14), VALUE(SUBSTITUTE(INDEX(SPLIT(IF(ISBLANK(R14), Q14, R14), "" km""), 0, 1), "" "", """")) - O14 = 0), """", IF(ISBLANK(R14), VALUE(SUBSTITUTE(INDEX(SPLIT(Q14, "" km""), 0, 1), "" "", """")) - O14, VALUE(SUBSTITUTE(INDEX(SPL"&"IT(R14, "" km""), 0, 1), "" "", """")) - O14))"),2000.0) -> 2000 | Q14: =IF(AND(ISBLANK(N14), ISBLANK(E14), ISBLANK(R14)), "", IF(ISBLANK(R14), TEXT(N14, "#,##0") & " Km, " & TEXT(E14, "dd.mm.yyyy"), R14)) -> 33 000 Km, 31.10.2022 | S14: 3300 | U14: @Maxmironov | V14: приличный небольшой опыт есть | W14: =IF(F14 = "", "", IF(NOW() > (DATEVALUE(LEFT(F14, SEARCH(",", F14) - 2)) + TIMEVALUE(MID(F14, SEARCH(",", F14) + 2, 5))), "Завершена", "В аренде")) -> Завершена | X14: =IFERROR(__xludf.DUMMYFUNCTION("IF(C14 = """", """", IF(REGEXMATCH(C14, ""PCX|NMAX|ADV|CLICK""), ""скутер"", ""мото""))"),"скутер") -> скутер
A15: Завершена | B15: OFF | C15: NMAX 155CC GREY PHUKET 5960 | D15: Дмитрий Чуканов | E15: 44866 | F15: 44933 | G15: =IF((E15="")+(F15=""), "", IF(DATEDIF(E15, F15, "d") > 30, DATEDIF(E15, F15, "m") & " М", DATEDIF(E15, F15, "d") & " Д")) -> 2 М | H15: 350 | I15: =IF(OR(A15="в аренде", A15="в аренде 1", A15="в аренде 2"), J15-K15, "") | J15: =IF(OR(A15="в аренде", A15="в аренде 1", A15="в аренде 2"), DATEDIF(E15, TODAY(), "D")*H15, "") | K15: 2800 | N15: 15600 | O15: =IFERROR(__xludf.DUMMYFUNCTION("IFERROR( VLOOKUP(C15, FILTER( IMPORTRANGE(""https://docs.google.com/spreadsheets/d/1ZBCmVvzoFu7X0td7O5T5xSJplK8m8h9wvdESBc0a1EE/edit#gid=1841437934"", ""Лист1!$C:$I""), IMPORTRANGE(""https://docs.google.com/spreadsheets/d/1ZBCmVvzoFu7X0"&"td7O5T5xSJplK8m8h9wvdESBc0a1EE/edit#gid=1841437934"", ""Лист1!$C:$C"") = C15 ), 7, FALSE ), """" ) "),37300.0) -> 37300 | P15: =IFERROR(__xludf.DUMMYFUNCTION("IF(OR(ISBLANK(Q15), ISBLANK(O15), VALUE(SUBSTITUTE(INDEX(SPLIT(IF(ISBLANK(R15), Q15, R15), "" km""), 0, 1), "" "", """")) - O15 = 0), """", IF(ISBLANK(R15), VALUE(SUBSTITUTE(INDEX(SPLIT(Q15, "" km""), 0, 1), "" "", """")) - O15, VALUE(SUBSTITUTE(INDEX(SPL"&"IT(R15, "" km""), 0, 1), "" "", """")) - O15))"),-21700.0) -> -21700 | Q15: =IF(AND(ISBLANK(N15), ISBLANK(E15), ISBLANK(R15)), "", IF(ISBLANK(R15), TEXT(N15, "#,##0") & " Km, " & TEXT(E15, "dd.mm.yyyy"), R15)) -> 15 600 Km, 01.11.2022 | S15: 3000 | T15: 1 | U15: @Dmitry_Tch | V15: старнный какойто | W15: =IF(F15 = "", "", IF(NOW() > (DATEVALUE(LEFT(F15, SEARCH(",", F15) - 2)) + TIMEVALUE(MID(F15, SEARCH(",", F15) + 2, 5))), "Завершена", "В аренде")) -> Завершена | X15: =IFERROR(__xludf.DUMMYFUNCTION("IF(C15 = """", """", IF(REGEXMATCH(C15, ""PCX|NMAX|ADV|CLICK""), ""скутер"", ""мото""))"),"скутер") -> скутер
A16: Завершена | B16: OFF | C16: NMAX 155CC YCONNECT BKK | D16: Евгений | E16: 44867 | F16: 45048 | G16: =IF((E16="")+(F16=""), "", IF(DATEDIF(E16, F16, "d") > 30, DATEDIF(E16, F16, "m") & " М", DATEDIF(E16, F16, "d") & " Д")) -> 6 М | H16: =7000/30 -> 233.33333 | I16: =IF(OR(A16="в аренде", A16="в аренде 1", A16="в аренде 2"), J16-K16, "") | J16: =IF(OR(A16="в аренде", A16="в аренде 1", A16="в аренде 2"), DATEDIF(E16, TODAY(), "D")*H16, "") | K16: =7000+7000+7000+7000+7000+7000 -> 42000 | N16: 9916 | O16: =IFERROR(__xludf.DUMMYFUNCTION("IFERROR( VLOOKUP(C16, FILTER( IMPORTRANGE(""https://docs.google.com/spreadsheets/d/1ZBCmVvzoFu7X0td7O5T5xSJplK8m8h9wvdESBc0a1EE/edit#gid=1841437934"", ""Лист1!$C:$I""), IMPORTRANGE(""https://docs.google.com/spreadsheets/d/1ZBCmVvzoFu7X0"&"td7O5T5xSJplK8m8h9wvdESBc0a1EE/edit#gid=1841437934"", ""Лист1!$C:$C"") = C16 ), 7, FALSE ), """" ) "),"") | P16: =IFERROR(__xludf.DUMMYFUNCTION("IF(OR(ISBLANK(Q16), ISBLANK(O16), VALUE(SUBSTITUTE(INDEX(SPLIT(IF(ISBLANK(R16), Q16, R16), "" km""), 0, 1), "" "", """")) - O16 = 0), """", IF(ISBLANK(R16), VALUE(SUBSTITUTE(INDEX(SPLIT(Q16, "" km""), 0, 1), "" "", """")) - O16, VALUE(SUBSTITUTE(INDEX(SPL"&"IT(R16, "" km""), 0, 1), "" "", """")) - O16))"),9916.0) -> 9916 | Q16: =IF(AND(ISBLANK(N16), ISBLANK(E16), ISBLANK(R16)), "", IF(ISBLANK(R16), TEXT(N16, "#,##0") & " Km, " & TEXT(E16, "dd.mm.yyyy"), R16)) -> 9 916 Km, 02.11.2022 | S16: 3000 | T16: 1 | U16: @adler_love | V16: норм чел привел много | W16: =IF(F16 = "", "", IF(NOW() > (DATEVALUE(LEFT(F16, SEARCH(",", F16) - 2)) + TIMEVALUE(MID(F16, SEARCH(",", F16) + 2, 5))), "Завершена", "В аренде")) -> Завершена | X16: =IFERROR(__xludf.DUMMYFUNCTION("IF(C16 = """", """", IF(REGEXMATCH(C16, ""PCX|NMAX|ADV|CLICK""), ""скутер"", ""мото""))"),"скутер") -> скутер
A17: Завершена | B17: OFF | C17: FORZA 300CC RED PHUKET 4244 | D17: Ramil | E17: 44868 | F17: 44938 | G17: =IF((E17="")+(F17=""), "", IF(DATEDIF(E17, F17, "d") > 30, DATEDIF(E17, F17, "m") & " М", DATEDIF(E17, F17, "d") & " Д")) -> 2 М | H17: =12000/30 -> 400 | I17: =IF(OR(A17="в аренде", A17="в аренде 1", A17="в аренде 2"), J17-K17, "") | J17: =IF(OR(A17="в аренде", A17="в аренде 1", A17="в аренде 2"), DATEDIF(E17, TODAY(), "D")*H17, "") | K17: =12000+12000+4000 -> 28000 | N17: 18000 | O17: =IFERROR(__xludf.DUMMYFUNCTION("IFERROR( VLOOKUP(C17, FILTER( IMPORTRANGE(""https://docs.google.com/spreadsheets/d/1ZBCmVvzoFu7X0td7O5T5xSJplK8m8h9wvdESBc0a1EE/edit#gid=1841437934"", ""Лист1!$C:$I""), IMPORTRANGE(""https://docs.google.com/spreadsheets/d/1ZBCmVvzoFu7X0"&"td7O5T5xSJplK8m8h9wvdESBc0a1EE/edit#gid=1841437934"", ""Лист1!$C:$C"") = C17 ), 7, FALSE ), """" ) "),"") | P17: =IFERROR(__xludf.DUMMYFUNCTION("IF(OR(ISBLANK(Q17), ISBLANK(O17), VALUE(SUBSTITUTE(INDEX(SPLIT(IF(ISBLANK(R17), Q17, R17), "" km""), 0, 1), "" "", """")) - O17 = 0), """", IF(ISBLANK(R17), VALUE(SUBSTITUTE(INDEX(SPLIT(Q17, "" km""), 0, 1), "" "", """")) - O17, VALUE(SUBSTITUTE(INDEX(SPL"&"IT(R17, "" km""), 0, 1), "" "", """")) - O17))"),18000.0) -> 18000 | Q17: =IF(AND(ISBLANK(N17), ISBLANK(E17), ISBLANK(R17)), "", IF(ISBLANK(R17), TEXT(N17, "#,##0") & " Km, " & TEXT(E17, "dd.mm.yyyy"), R17)) -> 18 000 Km, 03.11.2022 | S17: 5000 | T17: 1 | U17: @Ra_boss111 | V17: Взрослый ровный чел | W17: =IF(F17 = "", "", IF(NOW() > (DATEVALUE(LEFT(F17, SEARCH(",", F17) - 2)) + TIMEVALUE(MID(F17, SEARCH(",", F17) + 2, 5))), "Завершена", "В аренде")) -> Завершена | X17: =IFERROR(__xludf.DUMMYFUNCTION("IF(C17 = """", """", IF(REGEXMATCH(C17, ""PCX|NMAX|ADV|CLICK""), ""скутер"", ""мото""))"),"мото") -> мото
A18: Завершена | B18: OFF | C18: NMAX 155CC GREY MATT PHUKET 7527 | D18: Александр Ильин | E18: 44870 | F18: 44893 | G18: =IF((E18="")+(F18=""), "", IF(DATEDIF(E18, F18, "d") > 30, DATEDIF(E18, F18, "m") & " М", DATEDIF(E18, F18, "d") & " Д")) -> 23 Д | H18: =7000/30 -> 233.33333 | I18: =IF(OR(A18="в аренде", A18="в аренде 1", A18="в аренде 2"), J18-K18, "") | J18: =IF(OR(A18="в аренде", A18="в аренде 1", A18="в аренде 2"), DATEDIF(E18, TODAY(), "D")*H18, "") | K18: 5367 | N18: 12400 | O18: =IFERROR(__xludf.DUMMYFUNCTION("IFERROR( VLOOKUP(C18, FILTER( IMPORTRANGE(""https://docs.google.com/spreadsheets/d/1ZBCmVvzoFu7X0td7O5T5xSJplK8m8h9wvdESBc0a1EE/edit#gid=1841437934"", ""Лист1!$C:$I""), IMPORTRANGE(""https://docs.google.com/spreadsheets/d/1ZBCmVvzoFu7X0"&"td7O5T5xSJplK8m8h9wvdESBc0a1EE/edit#gid=1841437934"", ""Лист1!$C:$C"") = C18 ), 7, FALSE ), """" ) "),"") | P18: =IFERROR(__xludf.DUMMYFUNCTION("IF(OR(ISBLANK(Q18), ISBLANK(O18), VALUE(SUBSTITUTE(INDEX(SPLIT(IF(ISBLANK(R18), Q18, R18), "" km""), 0, 1), "" "", """")) - O18 = 0), """", IF(ISBLANK(R18), VALUE(SUBSTITUTE(INDEX(SPLIT(Q18, "" km""), 0, 1), "" "", """")) - O18, VALUE(SUBSTITUTE(INDEX(SPL"&"IT(R18, "" km""), 0, 1), "" "", """")) - O18))"),12400.0) -> 12400 | Q18: =IF(AND(ISBLANK(N18), ISBLANK(E18), ISBLANK(R18)), "", IF(ISBLANK(R18), TEXT(N18, "#,##0") & " Km, " & TEXT(E18, "dd.mm.yyyy"), R18)) -> 12 400 Km, 05.11.2022 | S18: 3000 | T18: 1 | U18: @Alex_hetzer | V18: немного странный но ок опыт не большой | W18: =IF(F18 = "", "", IF(NOW() > (DATEVALUE(LEFT(F18, SEARCH(",", F18) - 2)) + TIMEVALUE(MID(F18, SEARCH(",", F18) + 2, 5))), "Завершена", "В аренде")) -> Завершена | X18: =IFERROR(__xludf.DUMMYFUNCTION("IF(C18 = """", """", IF(REGEXMATCH(C18, ""PCX|NMAX|ADV|CLICK""), ""скутер"", ""мото""))"),"скутер") -> скутер
A19: Завершена | B19: OFF | C19: XMAX 300CC BLUE PHUKET 5773 | D19: Евгений | E19: 44872 | F19: 44893 | G19: =IF((E19="")+(F19=""), "", IF(DATEDIF(E19, F19, "d") > 30, DATEDIF(E19, F19, "m") & " М", DATEDIF(E19, F19, "d") & " Д")) -> 21 Д | H19: 480 | I19: =IF(OR(A19="в аренде", A19="в аренде 1", A19="в аренде 2"), J19-K19, "") | J19: =IF(OR(A19="в аренде", A19="в аренде 1", A19="в аренде 2"), DATEDIF(E19, TODAY(), "D")*H19, "") | K19: =1830+8250 -> 10080 | N19: 28600 | O19: =IFERROR(__xludf.DUMMYFUNCTION("IFERROR( VLOOKUP(C19, FILTER( IMPORTRANGE(""https://docs.google.com/spreadsheets/d/1ZBCmVvzoFu7X0td7O5T5xSJplK8m8h9wvdESBc0a1EE/edit#gid=1841437934"", ""Лист1!$C:$I""), IMPORTRANGE(""https://docs.google.com/spreadsheets/d/1ZBCmVvzoFu7X0"&"td7O5T5xSJplK8m8h9wvdESBc0a1EE/edit#gid=1841437934"", ""Лист1!$C:$C"") = C19 ), 7, FALSE ), """" ) "),23500.0) -> 23500 | P19: =IFERROR(__xludf.DUMMYFUNCTION("IF(OR(ISBLANK(Q19), ISBLANK(O19), VALUE(SUBSTITUTE(INDEX(SPLIT(IF(ISBLANK(R19), Q19, R19), "" km""), 0, 1), "" "", """")) - O19 = 0), """", IF(ISBLANK(R19), VALUE(SUBSTITUTE(INDEX(SPLIT(Q19, "" km""), 0, 1), "" "", """")) - O19, VALUE(SUBSTITUTE(INDEX(SPL"&"IT(R19, "" km""), 0, 1), "" "", """")) - O19))"),5100.0) -> 5100 | Q19: =IF(AND(ISBLANK(N19), ISBLANK(E19), ISBLANK(R19)), "", IF(ISBLANK(R19), TEXT(N19, "#,##0") & " Km, " & TEXT(E19, "dd.mm.yyyy"), R19)) -> 28 600 Km, 07.11.2022 | S19: 5000 | T19: 1 | U19: @eallend | V19: приятный с большим опытом | W19: =IF(F19 = "", "", IF(NOW() > (DATEVALUE(LEFT(F19, SEARCH(",", F19) - 2)) + TIMEVALUE(MID(F19, SEARCH(",", F19) + 2, 5))), "Завершена", "В аренде")) -> Завершена | X19: =IFERROR(__xludf.DUMMYFUNCTION("IF(C19 = """", """", IF(REGEXMATCH(C19, ""PCX|NMAX|ADV|CLICK""), ""скутер"", ""мото""))"),"мото") -> мото
A20: Завершена | B20: OFF | C20: NMAX 155CC GREY PHUKET 5960 | D20: Николай | E20: 44874 | F20: 44881 | G20: =IF((E20="")+(F20=""), "", IF(DATEDIF(E20, F20, "d") > 30, DATEDIF(E20, F20, "m") & " М", DATEDIF(E20, F20, "d") & " Д")) -> 7 Д | H20: 300 | I20: =IF(OR(A20="в аренде", A20="в аренде 1", A20="в аренде 2"), J20-K20, "") | J20: =IF(OR(A20="в аренде", A20="в аренде 1", A20="в аренде 2"), DATEDIF(E20, TODAY(), "D")*H20, "") | K20: 2100 | N20: 15880 | O20: =IFERROR(__xludf.DUMMYFUNCTION("IFERROR( VLOOKUP(C20, FILTER( IMPORTRANGE(""https://docs.google.com/spreadsheets/d/1ZBCmVvzoFu7X0td7O5T5xSJplK8m8h9wvdESBc0a1EE/edit#gid=1841437934"", ""Лист1!$C:$I""), IMPORTRANGE(""https://docs.google.com/spreadsheets/d/1ZBCmVvzoFu7X0"&"td7O5T5xSJplK8m8h9wvdESBc0a1EE/edit#gid=1841437934"", ""Лист1!$C:$C"") = C20 ), 7, FALSE ), """" ) "),37300.0) -> 37300 | P20: =IFERROR(__xludf.DUMMYFUNCTION("IF(OR(ISBLANK(Q20), ISBLANK(O20), VALUE(SUBSTITUTE(INDEX(SPLIT(IF(ISBLANK(R20), Q20, R20), "" km""), 0, 1), "" "", """")) - O20 = 0), """", IF(ISBLANK(R20), VALUE(SUBSTITUTE(INDEX(SPLIT(Q20, "" km""), 0, 1), "" "", """")) - O20, VALUE(SUBSTITUTE(INDEX(SPL"&"IT(R20, "" km""), 0, 1), "" "", """")) - O20))"),-21420.0) -> -21420 | Q20: =IF(AND(ISBLANK(N20), ISBLANK(E20), ISBLANK(R20)), "", IF(ISBLANK(R20), TEXT(N20, "#,##0") & " Km, " & TEXT(E20, "dd.mm.yyyy"), R20)) -> 15 880 Km, 09.11.2022 | S20: 3000 | T20: 2 | U20: @npekshuev | V20: Ник др Артем | W20: =IF(F20 = "", "", IF(NOW() > (DATEVALUE(LEFT(F20, SEARCH(",", F20) - 2)) + TIMEVALUE(MID(F20, SEARCH(",", F20) + 2, 5))), "Завершена", "В аренде")) -> Завершена | X20: =IFERROR(__xludf.DUMMYFUNCTION("IF(C20 = """", """", IF(REGEXMATCH(C20, ""PCX|NMAX|ADV|CLICK""), ""скутер"", ""мото""))"),"скутер") -> скутер
A21: Завершена | B21: OFF | C21: NMAX 155CC GREY GOLD PHUKET 6908 | D21: Roman | E21: 44875 | F21: 44905 | G21: =IF((E21="")+(F21=""), "", IF(DATEDIF(E21, F21, "d") > 30, DATEDIF(E21, F21, "m") & " М", DATEDIF(E21, F21, "d") & " Д")) -> 30 Д | H21: =7500/30 -> 250 | I21: =IF(OR(A21="в аренде", A21="в аренде 1", A21="в аренде 2"), J21-K21, "") | J21: =IF(OR(A21="в аренде", A21="в аренде 1", A21="в аренде 2"), DATEDIF(E21, TODAY(), "D")*H21, "") | K21: 7500 | N21: 23400 | O21: =IFERROR(__xludf.DUMMYFUNCTION("IFERROR( VLOOKUP(C21, FILTER( IMPORTRANGE(""https://docs.google.com/spreadsheets/d/1ZBCmVvzoFu7X0td7O5T5xSJplK8m8h9wvdESBc0a1EE/edit#gid=1841437934"", ""Лист1!$C:$I""), IMPORTRANGE(""https://docs.google.com/spreadsheets/d/1ZBCmVvzoFu7X0"&"td7O5T5xSJplK8m8h9wvdESBc0a1EE/edit#gid=1841437934"", ""Лист1!$C:$C"") = C21 ), 7, FALSE ), """" ) "),32200.0) -> 32200 | P21: =IFERROR(__xludf.DUMMYFUNCTION("IF(OR(ISBLANK(Q21), ISBLANK(O21), VALUE(SUBSTITUTE(INDEX(SPLIT(IF(ISBLANK(R21), Q21, R21), "" km""), 0, 1), "" "", """")) - O21 = 0), """", IF(ISBLANK(R21), VALUE(SUBSTITUTE(INDEX(SPLIT(Q21, "" km""), 0, 1), "" "", """")) - O21, VALUE(SUBSTITUTE(INDEX(SPL"&"IT(R21, "" km""), 0, 1), "" "", """")) - O21))"),-8800.0) -> -8800 | Q21: =IF(AND(ISBLANK(N21), ISBLANK(E21), ISBLANK(R21)), "", IF(ISBLANK(R21), TEXT(N21, "#,##0") & " Km, " & TEXT(E21, "dd.mm.yyyy"), R21)) -> 23 400 Km, 10.11.2022 | S21: 3000 | T21: 1 | U21: @futuroman | V21: украинец резкий но норм | W21: =IF(F21 = "", "", IF(NOW() > (DATEVALUE(LEFT(F21, SEARCH(",", F21) - 2)) + TIMEVALUE(MID(F21, SEARCH(",", F21) + 2, 5))), "Завершена", "В аренде")) -> Завершена | X21: =IFERROR(__xludf.DUMMYFUNCTION("IF(C21 = """", """", IF(REGEXMATCH(C21, ""PCX|NMAX|ADV|CLICK""), ""скутер"", ""мото""))"),"скутер") -> скутер
A22: Завершена | B22: OFF | C22: CBR 650R PHUKET 4505 | D22: Артем Тимофеев | E22: 44876 | F22: 44879 | G22: =IF((E22="")+(F22=""), "", IF(DATEDIF(E22, F22, "d") > 30, DATEDIF(E22, F22, "m") & " М", DATEDIF(E22, F22, "d") & " Д")) -> 3 Д | H22: =2500 -> 2500 | I22: =IF(OR(A22="в аренде", A22="в аренде 1", A22="в аренде 2"), J22-K22, "") | J22: =IF(OR(A22="в аренде", A22="в аренде 1", A22="в аренде 2"), DATEDIF(E22, TODAY(), "D")*H22, "") | K22: 8500 | N22: 26600 | O22: =IFERROR(__xludf.DUMMYFUNCTION("IFERROR( VLOOKUP(C22, FILTER( IMPORTRANGE(""https://docs.google.com/spreadsheets/d/1ZBCmVvzoFu7X0td7O5T5xSJplK8m8h9wvdESBc0a1EE/edit#gid=1841437934"", ""Лист1!$C:$I""), IMPORTRANGE(""https://docs.google.com/spreadsheets/d/1ZBCmVvzoFu7X0"&"td7O5T5xSJplK8m8h9wvdESBc0a1EE/edit#gid=1841437934"", ""Лист1!$C:$C"") = C22 ), 7, FALSE ), """" ) "),63700.0) -> 63700 | P22: =IFERROR(__xludf.DUMMYFUNCTION("IF(OR(ISBLANK(Q22), ISBLANK(O22), VALUE(SUBSTITUTE(INDEX(SPLIT(IF(ISBLANK(R22), Q22, R22), "" km""), 0, 1), "" "", """")) - O22 = 0), """", IF(ISBLANK(R22), VALUE(SUBSTITUTE(INDEX(SPLIT(Q22, "" km""), 0, 1), "" "", """")) - O22, VALUE(SUBSTITUTE(INDEX(SPL"&"IT(R22, "" km""), 0, 1), "" "", """")) - O22))"),-37100.0) -> -37100 | Q22: =IF(AND(ISBLANK(N22), ISBLANK(E22), ISBLANK(R22)), "", IF(ISBLANK(R22), TEXT(N22, "#,##0") & " Km, " & TEXT(E22, "dd.mm.yyyy"), R22)) -> 26 600 Km, 11.11.2022 | S22: 300 | T22: 1 | U22: +79138112101 | V22: вроде опытный здоровяк | W22: =IF(F22 = "", "", IF(NOW() > (DATEVALUE(LEFT(F22, SEARCH(",", F22) - 2)) + TIMEVALUE(MID(F22, SEARCH(",", F22) + 2, 5))), "Завершена", "В аренде")) -> Завершена | X22: =IFERROR(__xludf.DUMMYFUNCTION("IF(C22 = """", """", IF(REGEXMATCH(C22, ""PCX|NMAX|ADV|CLICK""), ""скутер"", ""мото""))"),"мото") -> мото
A23: Завершена | B23: OFF | C23: NMAX 155CC RACE PHUKET 7532 | D23: Антон | E23: 44877 | F23: 45028 | G23: =IF((E23="")+(F23=""), "", IF(DATEDIF(E23, F23, "d") > 30, DATEDIF(E23, F23, "m") & " М", DATEDIF(E23, F23, "d") & " Д")) -> 5 М | H23: =7000/30 -> 233.33333 | I23: =IF(OR(A23="в аренде", A23="в аренде 1", A23="в аренде 2"), J23-K23, "") | J23: =IF(OR(A23="в аренде", A23="в аренде 1", A23="в аренде 2"), DATEDIF(E23, TODAY(), "D")*H23, "") | K23: =14000+14000+7000 -> 35000 | N23: 13300 | O23: =IFERROR(__xludf.DUMMYFUNCTION("IFERROR( VLOOKUP(C23, FILTER( IMPORTRANGE(""https://docs.google.com/spreadsheets/d/1ZBCmVvzoFu7X0td7O5T5xSJplK8m8h9wvdESBc0a1EE/edit#gid=1841437934"", ""Лист1!$C:$I""), IMPORTRANGE(""https://docs.google.com/spreadsheets/d/1ZBCmVvzoFu7X0"&"td7O5T5xSJplK8m8h9wvdESBc0a1EE/edit#gid=1841437934"", ""Лист1!$C:$C"") = C23 ), 7, FALSE ), """" ) "),26000.0) -> 26000 | P23: =IFERROR(__xludf.DUMMYFUNCTION("IF(OR(ISBLANK(Q23), ISBLANK(O23), VALUE(SUBSTITUTE(INDEX(SPLIT(IF(ISBLANK(R23), Q23, R23), "" km""), 0, 1), "" "", """")) - O23 = 0), """", IF(ISBLANK(R23), VALUE(SUBSTITUTE(INDEX(SPLIT(Q23, "" km""), 0, 1), "" "", """")) - O23, VALUE(SUBSTITUTE(INDEX(SPL"&"IT(R23, "" km""), 0, 1), "" "", """")) - O23))"),"#VALUE!") -> #VALUE! | Q23: =IF(AND(ISBLANK(N23), ISBLANK(E23), ISBLANK(R23)), "", IF(ISBLANK(R23), TEXT(N23, "#,##0") & " Km, " & TEXT(E23, "dd.mm.yyyy"), R23)) -> хочет на год | R23: хочет на год | S23: 0 | T23: 2 | U23: @rebmalad | V23: добрый казах | W23: =IF(F23 = "", "", IF(NOW() > (DATEVALUE(LEFT(F23, SEARCH(",", F23) - 2)) + TIMEVALUE(MID(F23, SEARCH(",", F23) + 2, 5))), "Завершена", "В аренде")) -> Завершена | X23: =IFERROR(__xludf.DUMMYFUNCTION("IF(C23 = """", """", IF(REGEXMATCH(C23, ""PCX|NMAX|ADV|CLICK""), ""скутер"", ""мото""))"),"скутер") -> скутер
A24: Завершена | B24: OFF | C24: XMAX 300CC GREY PHUKET 4246 | D24: Сергей | E24: 44878 | F24: 44970 | G24: =IF((E24="")+(F24=""), "", IF(DATEDIF(E24, F24, "d") > 30, DATEDIF(E24, F24, "m") & " М", DATEDIF(E24, F24, "d") & " Д")) -> 3 М | H24: =12000/30 -> 400 | I24: =IF(OR(A24="в аренде", A24="в аренде 1", A24="в аренде 2"), J24-K24, "") | J24: =IF(OR(A24="в аренде", A24="в аренде 1", A24="в аренде 2"), DATEDIF(E24, TODAY(), "D")*H24, "") | K24: =12000+12000+12000+2100 -> 38100 | N24: 13900 | O24: =IFERROR(__xludf.DUMMYFUNCTION("IFERROR( VLOOKUP(C24, FILTER( IMPORTRANGE(""https://docs.google.com/spreadsheets/d/1ZBCmVvzoFu7X0td7O5T5xSJplK8m8h9wvdESBc0a1EE/edit#gid=1841437934"", ""Лист1!$C:$I""), IMPORTRANGE(""https://docs.google.com/spreadsheets/d/1ZBCmVvzoFu7X0"&"td7O5T5xSJplK8m8h9wvdESBc0a1EE/edit#gid=1841437934"", ""Лист1!$C:$C"") = C24 ), 7, FALSE ), """" ) "),38640.0) -> 38640 | P24: =IFERROR(__xludf.DUMMYFUNCTION("IF(OR(ISBLANK(Q24), ISBLANK(O24), VALUE(SUBSTITUTE(INDEX(SPLIT(IF(ISBLANK(R24), Q24, R24), "" km""), 0, 1), "" "", """")) - O24 = 0), """", IF(ISBLANK(R24), VALUE(SUBSTITUTE(INDEX(SPLIT(Q24, "" km""), 0, 1), "" "", """")) - O24, VALUE(SUBSTITUTE(INDEX(SPL"&"IT(R24, "" km""), 0, 1), "" "", """")) - O24))"),-24740.0) -> -24740 | Q24: =IF(AND(ISBLANK(N24), ISBLANK(E24), ISBLANK(R24)), "", IF(ISBLANK(R24), TEXT(N24, "#,##0") & " Km, " & TEXT(E24, "dd.mm.yyyy"), R24)) -> 13 900 Km, 13.11.2022 | S24: 5000 | T24: 2 | U24: @d_kryzhko | V24: опытный пара адекватных:))))))) | W24: =IF(F24 = "", "", IF(NOW() > (DATEVALUE(LEFT(F24, SEARCH(",", F24) - 2)) + TIMEVALUE(MID(F24, SEARCH(",", F24) + 2, 5))), "Завершена", "В аренде")) -> Завершена | X24: =IFERROR(__xludf.DUMMYFUNCTION("IF(C24 = """", """", IF(REGEXMATCH(C24, ""PCX|NMAX|ADV|CLICK""), ""скутер"", ""мото""))"),"мото") -> мото
A25: Завершена | B25: OFF | C25: XMAX 300CC 2020 BLACKGOLD PHUKET 3163 | D25: Николай | E25: 44883 | F25: 45006 | G25: =IF((E25="")+(F25=""), "", IF(DATEDIF(E25, F25, "d") > 30, DATEDIF(E25, F25, "m") & " М", DATEDIF(E25, F25, "d") & " Д")) -> 4 М | H25: =13000/30 -> 433.33333 | I25: =IF(OR(A25="в аренде", A25="в аренде 1", A25="в аренде 2"), J25-K25, "") | J25: =IF(OR(A25="в аренде", A25="в аренде 1", A25="в аренде 2"), DATEDIF(E25, TODAY(), "D")*H25, "") | K25: =13000+13000+13000+13000 -> 52000 | N25: 15880 | O25: =IFERROR(__xludf.DUMMYFUNCTION("IFERROR( VLOOKUP(C25, FILTER( IMPORTRANGE(""https://docs.google.com/spreadsheets/d/1ZBCmVvzoFu7X0td7O5T5xSJplK8m8h9wvdESBc0a1EE/edit#gid=1841437934"", ""Лист1!$C:$I""), IMPORTRANGE(""https://docs.google.com/spreadsheets/d/1ZBCmVvzoFu7X0"&"td7O5T5xSJplK8m8h9wvdESBc0a1EE/edit#gid=1841437934"", ""Лист1!$C:$C"") = C25 ), 7, FALSE ), """" ) "),"") | P25: =IFERROR(__xludf.DUMMYFUNCTION("IF(OR(ISBLANK(Q25), ISBLANK(O25), VALUE(SUBSTITUTE(INDEX(SPLIT(IF(ISBLANK(R25), Q25, R25), "" km""), 0, 1), "" "", """")) - O25 = 0), """", IF(ISBLANK(R25), VALUE(SUBSTITUTE(INDEX(SPLIT(Q25, "" km""), 0, 1), "" "", """")) - O25, VALUE(SUBSTITUTE(INDEX(SPL"&"IT(R25, "" km""), 0, 1), "" "", """")) - O25))"),15880.0) -> 15880 | Q25: =IF(AND(ISBLANK(N25), ISBLANK(E25), ISBLANK(R25)), "", IF(ISBLANK(R25), TEXT(N25, "#,##0") & " Km, " & TEXT(E25, "dd.mm.yyyy"), R25)) -> 15 880 Km, 18.11.2022 | S25: 5000 | T25: 2 | U25: @npekshuev | V25: Ник др Артем | W25: =IF(F25 = "", "", IF(NOW() > (DATEVALUE(LEFT(F25, SEARCH(",", F25) - 2)) + TIMEVALUE(MID(F25, SEARCH(",", F25) + 2, 5))), "Завершена", "В аренде")) -> Завершена | X25: =IFERROR(__xludf.DUMMYFUNCTION("IF(C25 = """", """", IF(REGEXMATCH(C25, ""PCX|NMAX|ADV|CLICK""), ""скутер"", ""мото""))"),"мото") -> мото
A26: Завершена | B26: OFF | C26: NMAX 155CC RED WHITE PHUKET 9548 | D26: Сева и Аня | E26: 44885 | F26: 45009 | G26: =IF((E26="")+(F26=""), "", IF(DATEDIF(E26, F26, "d") > 30, DATEDIF(E26, F26, "m") & " М", DATEDIF(E26, F26, "d") & " Д")) -> 4 М | H26: =8000/30 -> 266.66667 | I26: =IF(OR(A26="в аренде", A26="в аренде 1", A26="в аренде 2"), J26-K26, "") | J26: =IF(OR(A26="в аренде", A26="в аренде 1", A26="в аренде 2"), DATEDIF(E26, TODAY(), "D")*H26, "") | K26: =8000+8000+8000+8000+1070 -> 33070 | N26: 13800 | O26: =IFERROR(__xludf.DUMMYFUNCTION("IFERROR( VLOOKUP(C26, FILTER( IMPORTRANGE(""https://docs.google.com/spreadsheets/d/1ZBCmVvzoFu7X0td7O5T5xSJplK8m8h9wvdESBc0a1EE/edit#gid=1841437934"", ""Лист1!$C:$I""), IMPORTRANGE(""https://docs.google.com/spreadsheets/d/1ZBCmVvzoFu7X0"&"td7O5T5xSJplK8m8h9wvdESBc0a1EE/edit#gid=1841437934"", ""Лист1!$C:$C"") = C26 ), 7, FALSE ), """" ) "),31800.0) -> 31800 | P26: =IFERROR(__xludf.DUMMYFUNCTION("IF(OR(ISBLANK(Q26), ISBLANK(O26), VALUE(SUBSTITUTE(INDEX(SPLIT(IF(ISBLANK(R26), Q26, R26), "" km""), 0, 1), "" "", """")) - O26 = 0), """", IF(ISBLANK(R26), VALUE(SUBSTITUTE(INDEX(SPLIT(Q26, "" km""), 0, 1), "" "", """")) - O26, VALUE(SUBSTITUTE(INDEX(SPL"&"IT(R26, "" km""), 0, 1), "" "", """")) - O26))"),-18000.0) -> -18000 | Q26: =IF(AND(ISBLANK(N26), ISBLANK(E26), ISBLANK(R26)), "", IF(ISBLANK(R26), TEXT(N26, "#,##0") & " Km, " & TEXT(E26, "dd.mm.yyyy"), R26)) -> 13 800 Km, 20.11.2022 | S26: 3000 | T26: 2 | U26: @vnjutv | V26: 1 ый раз катаются | W26: =IF(F26 = "", "", IF(NOW() > (DATEVALUE(LEFT(F26, SEARCH(",", F26) - 2)) + TIMEVALUE(MID(F26, SEARCH(",", F26) + 2, 5))), "Завершена", "В аренде")) -> Завершена | X26: =IFERROR(__xludf.DUMMYFUNCTION("IF(C26 = """", """", IF(REGEXMATCH(C26, ""PCX|NMAX|ADV|CLICK""), ""скутер"", ""мото""))"),"скутер") -> скутер
A27: Завершена | B27: OFF | C27: NMAX 155CC GREY PHUKET 5960 | D27: Svetlana | E27: 44885 | F27: 45010 | G27: =IF((E27="")+(F27=""), "", IF(DATEDIF(E27, F27, "d") > 30, DATEDIF(E27, F27, "m") & " М", DATEDIF(E27, F27, "d") & " Д")) -> 4 М | H27: =7500/30 -> 250 | I27: =IF(OR(A27="в аренде", A27="в аренде 1", A27="в аренде 2"), J27-K27, "") | J27: =IF(OR(A27="в аренде", A27="в аренде 1", A27="в аренде 2"), DATEDIF(E27, TODAY(), "D")*H27, "") | K27: =8000+8000+8000+7500 -> 31500 | N27: 16100 | O27: =IFERROR(__xludf.DUMMYFUNCTION("IFERROR( VLOOKUP(C27, FILTER( IMPORTRANGE(""https://docs.google.com/spreadsheets/d/1ZBCmVvzoFu7X0td7O5T5xSJplK8m8h9wvdESBc0a1EE/edit#gid=1841437934"", ""Лист1!$C:$I""), IMPORTRANGE(""https://docs.google.com/spreadsheets/d/1ZBCmVvzoFu7X0"&"td7O5T5xSJplK8m8h9wvdESBc0a1EE/edit#gid=1841437934"", ""Лист1!$C:$C"") = C27 ), 7, FALSE ), """" ) "),37300.0) -> 37300 | P27: =IFERROR(__xludf.DUMMYFUNCTION("IF(OR(ISBLANK(Q27), ISBLANK(O27), VALUE(SUBSTITUTE(INDEX(SPLIT(IF(ISBLANK(R27), Q27, R27), "" km""), 0, 1), "" "", """")) - O27 = 0), """", IF(ISBLANK(R27), VALUE(SUBSTITUTE(INDEX(SPLIT(Q27, "" km""), 0, 1), "" "", """")) - O27, VALUE(SUBSTITUTE(INDEX(SPL"&"IT(R27, "" km""), 0, 1), "" "", """")) - O27))"),-21200.0) -> -21200 | Q27: =IF(AND(ISBLANK(N27), ISBLANK(E27), ISBLANK(R27)), "", IF(ISBLANK(R27), TEXT(N27, "#,##0") & " Km, " & TEXT(E27, "dd.mm.yyyy"), R27)) -> 16 100 Km, 20.11.2022 | S27: 3000 | T27: 2 | U27: @schvetko | V27: норм ребята пара | W27: =IF(F27 = "", "", IF(NOW() > (DATEVALUE(LEFT(F27, SEARCH(",", F27) - 2)) + TIMEVALUE(MID(F27, SEARCH(",", F27) + 2, 5))), "Завершена", "В аренде")) -> Завершена | X27: =IFERROR(__xludf.DUMMYFUNCTION("IF(C27 = """", """", IF(REGEXMATCH(C27, ""PCX|NMAX|ADV|CLICK""), ""скутер"", ""мото""))"),"скутер") -> скутер
A28: Завершена | B28: OFF | C28: NMAX 155CC GREEN MATT PHUKET 6901 | D28: Альберт | E28: 44885 | F28: 45016 | G28: =IF((E28="")+(F28=""), "", IF(DATEDIF(E28, F28, "d") > 30, DATEDIF(E28, F28, "m") & " М", DATEDIF(E28, F28, "d") & " Д")) -> 4 М | H28: =8000/30 -> 266.66667 | I28: =IF(OR(A28="в аренде", A28="в аренде 1", A28="в аренде 2"), J28-K28, "") | J28: =IF(OR(A28="в аренде", A28="в аренде 1", A28="в аренде 2"), DATEDIF(E28, TODAY(), "D")*H28, "") | K28: =8000+8000+8000 -> 24000 | N28: 19950 | O28: =IFERROR(__xludf.DUMMYFUNCTION("IFERROR( VLOOKUP(C28, FILTER( IMPORTRANGE(""https://docs.google.com/spreadsheets/d/1ZBCmVvzoFu7X0td7O5T5xSJplK8m8h9wvdESBc0a1EE/edit#gid=1841437934"", ""Лист1!$C:$I""), IMPORTRANGE(""https://docs.google.com/spreadsheets/d/1ZBCmVvzoFu7X0"&"td7O5T5xSJplK8m8h9wvdESBc0a1EE/edit#gid=1841437934"", ""Лист1!$C:$C"") = C28 ), 7, FALSE ), """" ) "),"") | P28: =IFERROR(__xludf.DUMMYFUNCTION("IF(OR(ISBLANK(Q28), ISBLANK(O28), VALUE(SUBSTITUTE(INDEX(SPLIT(IF(ISBLANK(R28), Q28, R28), "" km""), 0, 1), "" "", """")) - O28 = 0), """", IF(ISBLANK(R28), VALUE(SUBSTITUTE(INDEX(SPLIT(Q28, "" km""), 0, 1), "" "", """")) - O28, VALUE(SUBSTITUTE(INDEX(SPL"&"IT(R28, "" km""), 0, 1), "" "", """")) - O28))"),19950.0) -> 19950 | Q28: =IF(AND(ISBLANK(N28), ISBLANK(E28), ISBLANK(R28)), "", IF(ISBLANK(R28), TEXT(N28, "#,##0") & " Km, " & TEXT(E28, "dd.mm.yyyy"), R28)) -> 19 950 Km, 20.11.2022 | S28: 3000 | T28: 2 | U28: @KabirovAA | V28: ОКР | W28: =IF(F28 = "", "", IF(NOW() > (DATEVALUE(LEFT(F28, SEARCH(",", F28) - 2)) + TIMEVALUE(MID(F28, SEARCH(",", F28) + 2, 5))), "Завершена", "В аренде")) -> Завершена | X28: =IFERROR(__xludf.DUMMYFUNCTION("IF(C28 = """", """", IF(REGEXMATCH(C28, ""PCX|NMAX|ADV|CLICK""), ""скутер"", ""мото""))"),"скутер") -> скутер
A29: Завершена | B29: OFF | C29: NMAX 155CC GREEN MATT-2 PHUKET 7639 | D29: Константин | E29: 44887 | F29: 36892 | G29: =IF((E29="")+(F29=""), "", IF(DATEDIF(E29, F29, "d") > 30, DATEDIF(E29, F29, "m") & " М", DATEDIF(E29, F29, "d") & " Д")) -> #NUM! | H29: =8000/30 -> 266.66667 | I29: =IF(OR(A29="в аренде", A29="в аренде 1", A29="в аренде 2"), J29-K29, "") | J29: =IF(OR(A29="в аренде", A29="в аренде 1", A29="в аренде 2"), DATEDIF(E29, TODAY(), "D")*H29, "") | K29: =8000+8000+8000+8000 -> 32000 | N29: 31600 | O29: =IFERROR(__xludf.DUMMYFUNCTION("IFERROR( VLOOKUP(C29, FILTER( IMPORTRANGE(""https://docs.google.com/spreadsheets/d/1ZBCmVvzoFu7X0td7O5T5xSJplK8m8h9wvdESBc0a1EE/edit#gid=1841437934"", ""Лист1!$C:$I""), IMPORTRANGE(""https://docs.google.com/spreadsheets/d/1ZBCmVvzoFu7X0"&"td7O5T5xSJplK8m8h9wvdESBc0a1EE/edit#gid=1841437934"", ""Лист1!$C:$C"") = C29 ), 7, FALSE ), """" ) "),"") | P29: =IFERROR(__xludf.DUMMYFUNCTION("IF(OR(ISBLANK(Q29), ISBLANK(O29), VALUE(SUBSTITUTE(INDEX(SPLIT(IF(ISBLANK(R29), Q29, R29), "" km""), 0, 1), "" "", """")) - O29 = 0), """", IF(ISBLANK(R29), VALUE(SUBSTITUTE(INDEX(SPLIT(Q29, "" km""), 0, 1), "" "", """")) - O29, VALUE(SUBSTITUTE(INDEX(SPL"&"IT(R29, "" km""), 0, 1), "" "", """")) - O29))"),31600.0) -> 31600 | Q29: =IF(AND(ISBLANK(N29), ISBLANK(E29), ISBLANK(R29)), "", IF(ISBLANK(R29), TEXT(N29, "#,##0") & " Km, " & TEXT(E29, "dd.mm.yyyy"), R29)) -> 31 600 Km, 22.11.2022 | S29: 0 | T29: 2 | U29: @fansyl | V29: толпа из 4 человек намудрили с паспортом не опытные | W29: =IF(F29 = "", "", IF(NOW() > (DATEVALUE(LEFT(F29, SEARCH(",", F29) - 2)) + TIMEVALUE(MID(F29, SEARCH(",", F29) + 2, 5))), "Завершена", "В аренде")) -> #VALUE! | X29: =IFERROR(__xludf.DUMMYFUNCTION("IF(C29 = """", """", IF(REGEXMATCH(C29, ""PCX|NMAX|ADV|CLICK""), ""скутер"", ""мото""))"),"скутер") -> скутер
A30: Завершена | B30: OFF | C30: FORZA 300CC GREY PHUKET 4234 | D30: Владимир | E30: 44887 | F30: 44917 | G30: =IF((E30="")+(F30=""), "", IF(DATEDIF(E30, F30, "d") > 30, DATEDIF(E30, F30, "m") & " М", DATEDIF(E30, F30, "d") & " Д")) -> 30 Д | H30: =13000/30 -> 433.33333 | I30: =IF(OR(A30="в аренде", A30="в аренде 1", A30="в аренде 2"), J30-K30, "") | J30: =IF(OR(A30="в аренде", A30="в аренде 1", A30="в аренде 2"), DATEDIF(E30, TODAY(), "D")*H30, "") | K30: =13000+3467 -> 16467 | N30: 17800 | O30: =IFERROR(__xludf.DUMMYFUNCTION("IFERROR( VLOOKUP(C30, FILTER( IMPORTRANGE(""https://docs.google.com/spreadsheets/d/1ZBCmVvzoFu7X0td7O5T5xSJplK8m8h9wvdESBc0a1EE/edit#gid=1841437934"", ""Лист1!$C:$I""), IMPORTRANGE(""https://docs.google.com/spreadsheets/d/1ZBCmVvzoFu7X0"&"td7O5T5xSJplK8m8h9wvdESBc0a1EE/edit#gid=1841437934"", ""Лист1!$C:$C"") = C30 ), 7, FALSE ), """" ) "),"") | P30: =IFERROR(__xludf.DUMMYFUNCTION("IF(OR(ISBLANK(Q30), ISBLANK(O30), VALUE(SUBSTITUTE(INDEX(SPLIT(IF(ISBLANK(R30), Q30, R30), "" km""), 0, 1), "" "", """")) - O30 = 0), """", IF(ISBLANK(R30), VALUE(SUBSTITUTE(INDEX(SPLIT(Q30, "" km""), 0, 1), "" "", """")) - O30, VALUE(SUBSTITUTE(INDEX(SPL"&"IT(R30, "" km""), 0, 1), "" "", """")) - O30))"),17800.0) -> 17800 | Q30: =IF(AND(ISBLANK(N30), ISBLANK(E30), ISBLANK(R30)), "", IF(ISBLANK(R30), TEXT(N30, "#,##0") & " Km, " & TEXT(E30, "dd.mm.yyyy"), R30)) -> 17 800 Km, 22.11.2022 | S30: 5000 | T30: 3 | U30: @VoV51 | V30: гуд на спорте | W30: =IF(F30 = "", "", IF(NOW() > (DATEVALUE(LEFT(F30, SEARCH(",", F30) - 2)) + TIMEVALUE(MID(F30, SEARCH(",", F30) + 2, 5))), "Завершена", "В аренде")) -> Завершена | X30: =IFERROR(__xludf.DUMMYFUNCTION("IF(C30 = """", """", IF(REGEXMATCH(C30, ""PCX|NMAX|ADV|CLICK""), ""скутер"", ""мото""))"),"мото") -> мото
A31: Завершена | B31: OFF | C31: NMAX 155CC GREY NOSMART PHUKET 5508 | D31: Константин | E31: 44887 | F31: 44917 | G31: =IF((E31="")+(F31=""), "", IF(DATEDIF(E31, F31, "d") > 30, DATEDIF(E31, F31, "m") & " М", DATEDIF(E31, F31, "d") & " Д")) -> 30 Д | H31: =7000/30 -> 233.33333 | I31: =IF(OR(A31="в аренде", A31="в аренде 1", A31="в аренде 2"), J31-K31, "") | J31: =IF(OR(A31="в аренде", A31="в аренде 1", A31="в аренде 2"), DATEDIF(E31, TODAY(), "D")*H31, "") | K31: 7000 | N31: 24800 | O31: =IFERROR(__xludf.DUMMYFUNCTION("IFERROR( VLOOKUP(C31, FILTER( IMPORTRANGE(""https://docs.google.com/spreadsheets/d/1ZBCmVvzoFu7X0td7O5T5xSJplK8m8h9wvdESBc0a1EE/edit#gid=1841437934"", ""Лист1!$C:$I""), IMPORTRANGE(""https://docs.google.com/spreadsheets/d/1ZBCmVvzoFu7X0"&"td7O5T5xSJplK8m8h9wvdESBc0a1EE/edit#gid=1841437934"", ""Лист1!$C:$C"") = C31 ), 7, FALSE ), """" ) "),"") | P31: =IFERROR(__xludf.DUMMYFUNCTION("IF(OR(ISBLANK(Q31), ISBLANK(O31), VALUE(SUBSTITUTE(INDEX(SPLIT(IF(ISBLANK(R31), Q31, R31), "" km""), 0, 1), "" "", """")) - O31 = 0), """", IF(ISBLANK(R31), VALUE(SUBSTITUTE(INDEX(SPLIT(Q31, "" km""), 0, 1), "" "", """")) - O31, VALUE(SUBSTITUTE(INDEX(SPL"&"IT(R31, "" km""), 0, 1), "" "", """")) - O31))"),24800.0) -> 24800 | Q31: =IF(AND(ISBLANK(N31), ISBLANK(E31), ISBLANK(R31)), "", IF(ISBLANK(R31), TEXT(N31, "#,##0") & " Km, " & TEXT(E31, "dd.mm.yyyy"), R31)) -> 24 800 Km, 22.11.2022 | S31: 100 | T31: 2 | U31: @fansyl | V31: толпа из 4 человек намудрили с паспортом не опытные | W31: =IF(F31 = "", "", IF(NOW() > (DATEVALUE(LEFT(F31, SEARCH(",", F31) - 2)) + TIMEVALUE(MID(F31, SEARCH(",", F31) + 2, 5))), "Завершена", "В аренде")) -> Завершена | X31: =IFERROR(__xludf.DUMMYFUNCTION("IF(C31 = """", """", IF(REGEXMATCH(C31, ""PCX|NMAX|ADV|CLICK""), ""скутер"", ""мото""))"),"скутер") -> скутер
A32: Завершена | B32: OFF | C32: CLICK 125CC PHUKET 5580 | D32: Дмитрий | E32: 44888 | F32: 45008 | G32: =IF((E32="")+(F32=""), "", IF(DATEDIF(E32, F32, "d") > 30, DATEDIF(E32, F32, "m") & " М", DATEDIF(E32, F32, "d") & " Д")) -> 4 М | H32: =4000/30 -> 133.33333 | I32: =IF(OR(A32="в аренде", A32="в аренде 1", A32="в аренде 2"), J32-K32, "") | J32: =IF(OR(A32="в аренде", A32="в аренде 1", A32="в аренде 2"), DATEDIF(E32, TODAY(), "D")*H32, "") | K32: =4000+4000+200+4000+4000 -> 16200 | N32: 26800 | O32: =IFERROR(__xludf.DUMMYFUNCTION("IFERROR( VLOOKUP(C32, FILTER( IMPORTRANGE(""https://docs.google.com/spreadsheets/d/1ZBCmVvzoFu7X0td7O5T5xSJplK8m8h9wvdESBc0a1EE/edit#gid=1841437934"", ""Лист1!$C:$I""), IMPORTRANGE(""https://docs.google.com/spreadsheets/d/1ZBCmVvzoFu7X0"&"td7O5T5xSJplK8m8h9wvdESBc0a1EE/edit#gid=1841437934"", ""Лист1!$C:$C"") = C32 ), 7, FALSE ), """" ) "),33515.0) -> 33515 | P32: =IFERROR(__xludf.DUMMYFUNCTION("IF(OR(ISBLANK(Q32), ISBLANK(O32), VALUE(SUBSTITUTE(INDEX(SPLIT(IF(ISBLANK(R32), Q32, R32), "" km""), 0, 1), "" "", """")) - O32 = 0), """", IF(ISBLANK(R32), VALUE(SUBSTITUTE(INDEX(SPLIT(Q32, "" km""), 0, 1), "" "", """")) - O32, VALUE(SUBSTITUTE(INDEX(SPL"&"IT(R32, "" km""), 0, 1), "" "", """")) - O32))"),-6715.0) -> -6715 | Q32: =IF(AND(ISBLANK(N32), ISBLANK(E32), ISBLANK(R32)), "", IF(ISBLANK(R32), TEXT(N32, "#,##0") & " Km, " & TEXT(E32, "dd.mm.yyyy"), R32)) -> 26 800 Km, 23.11.2022 | S32: 3000 | T32: 1 | U32: @Valdman | V32: Дима из компании артема | W32: =IF(F32 = "", "", IF(NOW() > (DATEVALUE(LEFT(F32, SEARCH(",", F32) - 2)) + TIMEVALUE(MID(F32, SEARCH(",", F32) + 2, 5))), "Завершена", "В аренде")) -> Завершена | X32: =IFERROR(__xludf.DUMMYFUNCTION("IF(C32 = """", """", IF(REGEXMATCH(C32, ""PCX|NMAX|ADV|CLICK""), ""скутер"", ""мото""))"),"скутер") -> скутер
A33: Завершена | B33: OFF | C33: CBR 650R PHUKET 4505 | D33: Александр Степанов | E33: 44889 | F33: 44894 | G33: =IF((E33="")+(F33=""), "", IF(DATEDIF(E33, F33, "d") > 30, DATEDIF(E33, F33, "m") & " М", DATEDIF(E33, F33, "d") & " Д")) -> 5 Д | H33: 2200 | I33: =IF(OR(A33="в аренде", A33="в аренде 1", A33="в аренде 2"), J33-K33, "") | J33: =IF(OR(A33="в аренде", A33="в аренде 1", A33="в аренде 2"), DATEDIF(E33, TODAY(), "D")*H33, "") | K33: 11000 | N33: 27573 | O33: =IFERROR(__xludf.DUMMYFUNCTION("IFERROR( VLOOKUP(C33, FILTER( IMPORTRANGE(""https://docs.google.com/spreadsheets/d/1ZBCmVvzoFu7X0td7O5T5xSJplK8m8h9wvdESBc0a1EE/edit#gid=1841437934"", ""Лист1!$C:$I""), IMPORTRANGE(""https://docs.google.com/spreadsheets/d/1ZBCmVvzoFu7X0"&"td7O5T5xSJplK8m8h9wvdESBc0a1EE/edit#gid=1841437934"", ""Лист1!$C:$C"") = C33 ), 7, FALSE ), """" ) "),63700.0) -> 63700 | P33: =IFERROR(__xludf.DUMMYFUNCTION("IF(OR(ISBLANK(Q33), ISBLANK(O33), VALUE(SUBSTITUTE(INDEX(SPLIT(IF(ISBLANK(R33), Q33, R33), "" km""), 0, 1), "" "", """")) - O33 = 0), """", IF(ISBLANK(R33), VALUE(SUBSTITUTE(INDEX(SPLIT(Q33, "" km""), 0, 1), "" "", """")) - O33, VALUE(SUBSTITUTE(INDEX(SPL"&"IT(R33, "" km""), 0, 1), "" "", """")) - O33))"),-36127.0) -> -36127 | Q33: =IF(AND(ISBLANK(N33), ISBLANK(E33), ISBLANK(R33)), "", IF(ISBLANK(R33), TEXT(N33, "#,##0") & " Km, " & TEXT(E33, "dd.mm.yyyy"), R33)) -> 27 573 Km, 24.11.2022 | S33: 17000 | T33: 1 | U33: @fomLeyb | V33: опытный скромный | W33: =IF(F33 = "", "", IF(NOW() > (DATEVALUE(LEFT(F33, SEARCH(",", F33) - 2)) + TIMEVALUE(MID(F33, SEARCH(",", F33) + 2, 5))), "Завершена", "В аренде")) -> Завершена | X33: =IFERROR(__xludf.DUMMYFUNCTION("IF(C33 = """", """", IF(REGEXMATCH(C33, ""PCX|NMAX|ADV|CLICK""), ""скутер"", ""мото""))"),"мото") -> мото
A34: Завершена | B34: OFF | C34: NMAX 155CC GREY MATT PHUKET 7527 | D34: Алина Галеева | E34: 44893 | F34: 44976 | G34: =IF((E34="")+(F34=""), "", IF(DATEDIF(E34, F34, "d") > 30, DATEDIF(E34, F34, "m") & " М", DATEDIF(E34, F34, "d") & " Д")) -> 2 М | H34: =8000/30 -> 266.66667 | I34: =IF(OR(A34="в аренде", A34="в аренде 1", A34="в аренде 2"), J34-K34, "") | J34: =IF(OR(A34="в аренде", A34="в аренде 1", A34="в аренде 2"), DATEDIF(E34, TODAY(), "D")*H34, "") | K34: =12000+8000+2670 -> 22670 | N34: 13300 | O34: =IFERROR(__xludf.DUMMYFUNCTION("IFERROR( VLOOKUP(C34, FILTER( IMPORTRANGE(""https://docs.google.com/spreadsheets/d/1ZBCmVvzoFu7X0td7O5T5xSJplK8m8h9wvdESBc0a1EE/edit#gid=1841437934"", ""Лист1!$C:$I""), IMPORTRANGE(""https://docs.google.com/spreadsheets/d/1ZBCmVvzoFu7X0"&"td7O5T5xSJplK8m8h9wvdESBc0a1EE/edit#gid=1841437934"", ""Лист1!$C:$C"") = C34 ), 7, FALSE ), """" ) "),"") | P34: =IFERROR(__xludf.DUMMYFUNCTION("IF(OR(ISBLANK(Q34), ISBLANK(O34), VALUE(SUBSTITUTE(INDEX(SPLIT(IF(ISBLANK(R34), Q34, R34), "" km""), 0, 1), "" "", """")) - O34 = 0), """", IF(ISBLANK(R34), VALUE(SUBSTITUTE(INDEX(SPLIT(Q34, "" km""), 0, 1), "" "", """")) - O34, VALUE(SUBSTITUTE(INDEX(SPL"&"IT(R34, "" km""), 0, 1), "" "", """")) - O34))"),13300.0) -> 13300 | Q34: =IF(AND(ISBLANK(N34), ISBLANK(E34), ISBLANK(R34)), "", IF(ISBLANK(R34), TEXT(N34, "#,##0") & " Km, " & TEXT(E34, "dd.mm.yyyy"), R34)) -> 13 300 Km, 28.11.2022 | S34: 3000 | T34: 1 | U34: @alinochf | V34: медленная опыта не много | W34: =IF(F34 = "", "", IF(NOW() > (DATEVALUE(LEFT(F34, SEARCH(",", F34) - 2)) + TIMEVALUE(MID(F34, SEARCH(",", F34) + 2, 5))), "Завершена", "В аренде")) -> Завершена | X34: =IFERROR(__xludf.DUMMYFUNCTION("IF(C34 = """", """", IF(REGEXMATCH(C34, ""PCX|NMAX|ADV|CLICK""), ""скутер"", ""мото""))"),"скутер") -> скутер
